mkdir: cannot create directory ‘/scratch/general/vast/u1283221/huggingface_cache’: File exists
Traceback (most recent call last):
  File "/uufs/chpc.utah.edu/common/home/u1283221/miniconda3/envs/compositional/lib/python3.11/site-packages/huggingface_hub/utils/_errors.py", line 261, in hf_raise_for_status
    response.raise_for_status()
  File "/uufs/chpc.utah.edu/common/home/u1283221/miniconda3/envs/compositional/lib/python3.11/site-packages/requests/models.py", line 1021, in raise_for_status
    raise HTTPError(http_error_msg, response=self)
requests.exceptions.HTTPError: 401 Client Error: Unauthorized for url: https://huggingface.co/meta-llama/Llama-2-7b-chat-hf/resolve/main/tokenizer_config.json

The above exception was the direct cause of the following exception:

Traceback (most recent call last):
  File "/uufs/chpc.utah.edu/common/home/u1283221/miniconda3/envs/compositional/lib/python3.11/site-packages/transformers/utils/hub.py", line 428, in cached_file
    resolved_file = hf_hub_download(
                    ^^^^^^^^^^^^^^^^
  File "/uufs/chpc.utah.edu/common/home/u1283221/miniconda3/envs/compositional/lib/python3.11/site-packages/huggingface_hub/utils/_validators.py", line 118, in _inner_fn
    return fn(*args, **kwargs)
           ^^^^^^^^^^^^^^^^^^^
  File "/uufs/chpc.utah.edu/common/home/u1283221/miniconda3/envs/compositional/lib/python3.11/site-packages/huggingface_hub/file_download.py", line 1195, in hf_hub_download
    metadata = get_hf_file_metadata(
               ^^^^^^^^^^^^^^^^^^^^^
  File "/uufs/chpc.utah.edu/common/home/u1283221/miniconda3/envs/compositional/lib/python3.11/site-packages/huggingface_hub/utils/_validators.py", line 118, in _inner_fn
    return fn(*args, **kwargs)
           ^^^^^^^^^^^^^^^^^^^
  File "/uufs/chpc.utah.edu/common/home/u1283221/miniconda3/envs/compositional/lib/python3.11/site-packages/huggingface_hub/file_download.py", line 1541, in get_hf_file_metadata
    hf_raise_for_status(r)
  File "/uufs/chpc.utah.edu/common/home/u1283221/miniconda3/envs/compositional/lib/python3.11/site-packages/huggingface_hub/utils/_errors.py", line 277, in hf_raise_for_status
    raise GatedRepoError(message, response) from e
huggingface_hub.utils._errors.GatedRepoError: 401 Client Error. (Request ID: Root=1-64e8f028-2353723a31527c9d194e2dc8;eae71891-203f-4534-9875-8408f1bd55d2)

Cannot access gated repo for url https://huggingface.co/meta-llama/Llama-2-7b-chat-hf/resolve/main/tokenizer_config.json.
Repo model meta-llama/Llama-2-7b-chat-hf is gated. You must be authenticated to access it.

The above exception was the direct cause of the following exception:

Traceback (most recent call last):
  File "/uufs/chpc.utah.edu/common/home/u1283221/compositional_task_evaluation/llama2_cte.py", line 61, in <module>
    tokenizer = AutoTokenizer.from_pretrained("meta-llama/Llama-2-7b-chat-hf")
                ^^^^^^^^^^^^^^^^^^^^^^^^^^^^^^^^^^^^^^^^^^^^^^^^^^^^^^^^^^^^^^
  File "/uufs/chpc.utah.edu/common/home/u1283221/miniconda3/envs/compositional/lib/python3.11/site-packages/transformers/models/auto/tokenization_auto.py", line 677, in from_pretrained
    tokenizer_config = get_tokenizer_config(pretrained_model_name_or_path, **kwargs)
                       ^^^^^^^^^^^^^^^^^^^^^^^^^^^^^^^^^^^^^^^^^^^^^^^^^^^^^^^^^^^^^
  File "/uufs/chpc.utah.edu/common/home/u1283221/miniconda3/envs/compositional/lib/python3.11/site-packages/transformers/models/auto/tokenization_auto.py", line 510, in get_tokenizer_config
    resolved_config_file = cached_file(
                           ^^^^^^^^^^^^
  File "/uufs/chpc.utah.edu/common/home/u1283221/miniconda3/envs/compositional/lib/python3.11/site-packages/transformers/utils/hub.py", line 443, in cached_file
    raise EnvironmentError(
OSError: You are trying to access a gated repo.
Make sure to request access at https://huggingface.co/meta-llama/Llama-2-7b-chat-hf and pass a token having permission to this repo either by logging in with `huggingface-cli login` or by passing `token=<your_token>`.
Traceback (most recent call last):
  File "/uufs/chpc.utah.edu/common/home/u1283221/miniconda3/envs/compositional/lib/python3.11/site-packages/huggingface_hub/utils/_errors.py", line 261, in hf_raise_for_status
    response.raise_for_status()
  File "/uufs/chpc.utah.edu/common/home/u1283221/miniconda3/envs/compositional/lib/python3.11/site-packages/requests/models.py", line 1021, in raise_for_status
    raise HTTPError(http_error_msg, response=self)
requests.exceptions.HTTPError: 401 Client Error: Unauthorized for url: https://huggingface.co/meta-llama/Llama-2-7b-chat-hf/resolve/main/tokenizer_config.json

The above exception was the direct cause of the following exception:

Traceback (most recent call last):
  File "/uufs/chpc.utah.edu/common/home/u1283221/miniconda3/envs/compositional/lib/python3.11/site-packages/transformers/utils/hub.py", line 428, in cached_file
    resolved_file = hf_hub_download(
                    ^^^^^^^^^^^^^^^^
  File "/uufs/chpc.utah.edu/common/home/u1283221/miniconda3/envs/compositional/lib/python3.11/site-packages/huggingface_hub/utils/_validators.py", line 118, in _inner_fn
    return fn(*args, **kwargs)
           ^^^^^^^^^^^^^^^^^^^
  File "/uufs/chpc.utah.edu/common/home/u1283221/miniconda3/envs/compositional/lib/python3.11/site-packages/huggingface_hub/file_download.py", line 1195, in hf_hub_download
    metadata = get_hf_file_metadata(
               ^^^^^^^^^^^^^^^^^^^^^
  File "/uufs/chpc.utah.edu/common/home/u1283221/miniconda3/envs/compositional/lib/python3.11/site-packages/huggingface_hub/utils/_validators.py", line 118, in _inner_fn
    return fn(*args, **kwargs)
           ^^^^^^^^^^^^^^^^^^^
  File "/uufs/chpc.utah.edu/common/home/u1283221/miniconda3/envs/compositional/lib/python3.11/site-packages/huggingface_hub/file_download.py", line 1541, in get_hf_file_metadata
    hf_raise_for_status(r)
  File "/uufs/chpc.utah.edu/common/home/u1283221/miniconda3/envs/compositional/lib/python3.11/site-packages/huggingface_hub/utils/_errors.py", line 277, in hf_raise_for_status
    raise GatedRepoError(message, response) from e
huggingface_hub.utils._errors.GatedRepoError: 401 Client Error. (Request ID: Root=1-64e8f036-2be98ade5bec4d1f0cb48807;4ac22ae9-9e0c-41f7-9e84-c773bfa7f5d1)

Cannot access gated repo for url https://huggingface.co/meta-llama/Llama-2-7b-chat-hf/resolve/main/tokenizer_config.json.
Repo model meta-llama/Llama-2-7b-chat-hf is gated. You must be authenticated to access it.

The above exception was the direct cause of the following exception:

Traceback (most recent call last):
  File "/uufs/chpc.utah.edu/common/home/u1283221/compositional_task_evaluation/llama2_cte.py", line 61, in <module>
    tokenizer = AutoTokenizer.from_pretrained("meta-llama/Llama-2-7b-chat-hf")
                ^^^^^^^^^^^^^^^^^^^^^^^^^^^^^^^^^^^^^^^^^^^^^^^^^^^^^^^^^^^^^^
  File "/uufs/chpc.utah.edu/common/home/u1283221/miniconda3/envs/compositional/lib/python3.11/site-packages/transformers/models/auto/tokenization_auto.py", line 677, in from_pretrained
    tokenizer_config = get_tokenizer_config(pretrained_model_name_or_path, **kwargs)
                       ^^^^^^^^^^^^^^^^^^^^^^^^^^^^^^^^^^^^^^^^^^^^^^^^^^^^^^^^^^^^^
  File "/uufs/chpc.utah.edu/common/home/u1283221/miniconda3/envs/compositional/lib/python3.11/site-packages/transformers/models/auto/tokenization_auto.py", line 510, in get_tokenizer_config
    resolved_config_file = cached_file(
                           ^^^^^^^^^^^^
  File "/uufs/chpc.utah.edu/common/home/u1283221/miniconda3/envs/compositional/lib/python3.11/site-packages/transformers/utils/hub.py", line 443, in cached_file
    raise EnvironmentError(
OSError: You are trying to access a gated repo.
Make sure to request access at https://huggingface.co/meta-llama/Llama-2-7b-chat-hf and pass a token having permission to this repo either by logging in with `huggingface-cli login` or by passing `token=<your_token>`.
Traceback (most recent call last):
  File "/uufs/chpc.utah.edu/common/home/u1283221/miniconda3/envs/compositional/lib/python3.11/site-packages/huggingface_hub/utils/_errors.py", line 261, in hf_raise_for_status
    response.raise_for_status()
  File "/uufs/chpc.utah.edu/common/home/u1283221/miniconda3/envs/compositional/lib/python3.11/site-packages/requests/models.py", line 1021, in raise_for_status
    raise HTTPError(http_error_msg, response=self)
requests.exceptions.HTTPError: 401 Client Error: Unauthorized for url: https://huggingface.co/meta-llama/Llama-2-7b-chat-hf/resolve/main/tokenizer_config.json

The above exception was the direct cause of the following exception:

Traceback (most recent call last):
  File "/uufs/chpc.utah.edu/common/home/u1283221/miniconda3/envs/compositional/lib/python3.11/site-packages/transformers/utils/hub.py", line 428, in cached_file
    resolved_file = hf_hub_download(
                    ^^^^^^^^^^^^^^^^
  File "/uufs/chpc.utah.edu/common/home/u1283221/miniconda3/envs/compositional/lib/python3.11/site-packages/huggingface_hub/utils/_validators.py", line 118, in _inner_fn
    return fn(*args, **kwargs)
           ^^^^^^^^^^^^^^^^^^^
  File "/uufs/chpc.utah.edu/common/home/u1283221/miniconda3/envs/compositional/lib/python3.11/site-packages/huggingface_hub/file_download.py", line 1195, in hf_hub_download
    metadata = get_hf_file_metadata(
               ^^^^^^^^^^^^^^^^^^^^^
  File "/uufs/chpc.utah.edu/common/home/u1283221/miniconda3/envs/compositional/lib/python3.11/site-packages/huggingface_hub/utils/_validators.py", line 118, in _inner_fn
    return fn(*args, **kwargs)
           ^^^^^^^^^^^^^^^^^^^
  File "/uufs/chpc.utah.edu/common/home/u1283221/miniconda3/envs/compositional/lib/python3.11/site-packages/huggingface_hub/file_download.py", line 1541, in get_hf_file_metadata
    hf_raise_for_status(r)
  File "/uufs/chpc.utah.edu/common/home/u1283221/miniconda3/envs/compositional/lib/python3.11/site-packages/huggingface_hub/utils/_errors.py", line 277, in hf_raise_for_status
    raise GatedRepoError(message, response) from e
huggingface_hub.utils._errors.GatedRepoError: 401 Client Error. (Request ID: Root=1-64e8f03b-3c508f824377eb6744496d85;4d6948b1-1989-417e-b50c-1e6196459dcb)

Cannot access gated repo for url https://huggingface.co/meta-llama/Llama-2-7b-chat-hf/resolve/main/tokenizer_config.json.
Repo model meta-llama/Llama-2-7b-chat-hf is gated. You must be authenticated to access it.

The above exception was the direct cause of the following exception:

Traceback (most recent call last):
  File "/uufs/chpc.utah.edu/common/home/u1283221/compositional_task_evaluation/llama2_cte.py", line 61, in <module>
    tokenizer = AutoTokenizer.from_pretrained("meta-llama/Llama-2-7b-chat-hf")
                ^^^^^^^^^^^^^^^^^^^^^^^^^^^^^^^^^^^^^^^^^^^^^^^^^^^^^^^^^^^^^^
  File "/uufs/chpc.utah.edu/common/home/u1283221/miniconda3/envs/compositional/lib/python3.11/site-packages/transformers/models/auto/tokenization_auto.py", line 677, in from_pretrained
    tokenizer_config = get_tokenizer_config(pretrained_model_name_or_path, **kwargs)
                       ^^^^^^^^^^^^^^^^^^^^^^^^^^^^^^^^^^^^^^^^^^^^^^^^^^^^^^^^^^^^^
  File "/uufs/chpc.utah.edu/common/home/u1283221/miniconda3/envs/compositional/lib/python3.11/site-packages/transformers/models/auto/tokenization_auto.py", line 510, in get_tokenizer_config
    resolved_config_file = cached_file(
                           ^^^^^^^^^^^^
  File "/uufs/chpc.utah.edu/common/home/u1283221/miniconda3/envs/compositional/lib/python3.11/site-packages/transformers/utils/hub.py", line 443, in cached_file
    raise EnvironmentError(
OSError: You are trying to access a gated repo.
Make sure to request access at https://huggingface.co/meta-llama/Llama-2-7b-chat-hf and pass a token having permission to this repo either by logging in with `huggingface-cli login` or by passing `token=<your_token>`.
Traceback (most recent call last):
  File "/uufs/chpc.utah.edu/common/home/u1283221/miniconda3/envs/compositional/lib/python3.11/site-packages/huggingface_hub/utils/_errors.py", line 261, in hf_raise_for_status
    response.raise_for_status()
  File "/uufs/chpc.utah.edu/common/home/u1283221/miniconda3/envs/compositional/lib/python3.11/site-packages/requests/models.py", line 1021, in raise_for_status
    raise HTTPError(http_error_msg, response=self)
requests.exceptions.HTTPError: 401 Client Error: Unauthorized for url: https://huggingface.co/meta-llama/Llama-2-7b-chat-hf/resolve/main/tokenizer_config.json

The above exception was the direct cause of the following exception:

Traceback (most recent call last):
  File "/uufs/chpc.utah.edu/common/home/u1283221/miniconda3/envs/compositional/lib/python3.11/site-packages/transformers/utils/hub.py", line 428, in cached_file
    resolved_file = hf_hub_download(
                    ^^^^^^^^^^^^^^^^
  File "/uufs/chpc.utah.edu/common/home/u1283221/miniconda3/envs/compositional/lib/python3.11/site-packages/huggingface_hub/utils/_validators.py", line 118, in _inner_fn
    return fn(*args, **kwargs)
           ^^^^^^^^^^^^^^^^^^^
  File "/uufs/chpc.utah.edu/common/home/u1283221/miniconda3/envs/compositional/lib/python3.11/site-packages/huggingface_hub/file_download.py", line 1195, in hf_hub_download
    metadata = get_hf_file_metadata(
               ^^^^^^^^^^^^^^^^^^^^^
  File "/uufs/chpc.utah.edu/common/home/u1283221/miniconda3/envs/compositional/lib/python3.11/site-packages/huggingface_hub/utils/_validators.py", line 118, in _inner_fn
    return fn(*args, **kwargs)
           ^^^^^^^^^^^^^^^^^^^
  File "/uufs/chpc.utah.edu/common/home/u1283221/miniconda3/envs/compositional/lib/python3.11/site-packages/huggingface_hub/file_download.py", line 1541, in get_hf_file_metadata
    hf_raise_for_status(r)
  File "/uufs/chpc.utah.edu/common/home/u1283221/miniconda3/envs/compositional/lib/python3.11/site-packages/huggingface_hub/utils/_errors.py", line 277, in hf_raise_for_status
    raise GatedRepoError(message, response) from e
huggingface_hub.utils._errors.GatedRepoError: 401 Client Error. (Request ID: Root=1-64e8f03d-60fce92e5d7d0f43736bfe2f;61f76676-1af4-43a5-83a7-42c5d064aaea)

Cannot access gated repo for url https://huggingface.co/meta-llama/Llama-2-7b-chat-hf/resolve/main/tokenizer_config.json.
Repo model meta-llama/Llama-2-7b-chat-hf is gated. You must be authenticated to access it.

The above exception was the direct cause of the following exception:

Traceback (most recent call last):
  File "/uufs/chpc.utah.edu/common/home/u1283221/compositional_task_evaluation/llama2_cte.py", line 61, in <module>
    tokenizer = AutoTokenizer.from_pretrained("meta-llama/Llama-2-7b-chat-hf")
                ^^^^^^^^^^^^^^^^^^^^^^^^^^^^^^^^^^^^^^^^^^^^^^^^^^^^^^^^^^^^^^
  File "/uufs/chpc.utah.edu/common/home/u1283221/miniconda3/envs/compositional/lib/python3.11/site-packages/transformers/models/auto/tokenization_auto.py", line 677, in from_pretrained
    tokenizer_config = get_tokenizer_config(pretrained_model_name_or_path, **kwargs)
                       ^^^^^^^^^^^^^^^^^^^^^^^^^^^^^^^^^^^^^^^^^^^^^^^^^^^^^^^^^^^^^
  File "/uufs/chpc.utah.edu/common/home/u1283221/miniconda3/envs/compositional/lib/python3.11/site-packages/transformers/models/auto/tokenization_auto.py", line 510, in get_tokenizer_config
    resolved_config_file = cached_file(
                           ^^^^^^^^^^^^
  File "/uufs/chpc.utah.edu/common/home/u1283221/miniconda3/envs/compositional/lib/python3.11/site-packages/transformers/utils/hub.py", line 443, in cached_file
    raise EnvironmentError(
OSError: You are trying to access a gated repo.
Make sure to request access at https://huggingface.co/meta-llama/Llama-2-7b-chat-hf and pass a token having permission to this repo either by logging in with `huggingface-cli login` or by passing `token=<your_token>`.
Traceback (most recent call last):
  File "/uufs/chpc.utah.edu/common/home/u1283221/miniconda3/envs/compositional/lib/python3.11/site-packages/huggingface_hub/utils/_errors.py", line 261, in hf_raise_for_status
    response.raise_for_status()
  File "/uufs/chpc.utah.edu/common/home/u1283221/miniconda3/envs/compositional/lib/python3.11/site-packages/requests/models.py", line 1021, in raise_for_status
    raise HTTPError(http_error_msg, response=self)
requests.exceptions.HTTPError: 401 Client Error: Unauthorized for url: https://huggingface.co/meta-llama/Llama-2-7b-chat-hf/resolve/main/tokenizer_config.json

The above exception was the direct cause of the following exception:

Traceback (most recent call last):
  File "/uufs/chpc.utah.edu/common/home/u1283221/miniconda3/envs/compositional/lib/python3.11/site-packages/transformers/utils/hub.py", line 428, in cached_file
    resolved_file = hf_hub_download(
                    ^^^^^^^^^^^^^^^^
  File "/uufs/chpc.utah.edu/common/home/u1283221/miniconda3/envs/compositional/lib/python3.11/site-packages/huggingface_hub/utils/_validators.py", line 118, in _inner_fn
    return fn(*args, **kwargs)
           ^^^^^^^^^^^^^^^^^^^
  File "/uufs/chpc.utah.edu/common/home/u1283221/miniconda3/envs/compositional/lib/python3.11/site-packages/huggingface_hub/file_download.py", line 1195, in hf_hub_download
    metadata = get_hf_file_metadata(
               ^^^^^^^^^^^^^^^^^^^^^
  File "/uufs/chpc.utah.edu/common/home/u1283221/miniconda3/envs/compositional/lib/python3.11/site-packages/huggingface_hub/utils/_validators.py", line 118, in _inner_fn
    return fn(*args, **kwargs)
           ^^^^^^^^^^^^^^^^^^^
  File "/uufs/chpc.utah.edu/common/home/u1283221/miniconda3/envs/compositional/lib/python3.11/site-packages/huggingface_hub/file_download.py", line 1541, in get_hf_file_metadata
    hf_raise_for_status(r)
  File "/uufs/chpc.utah.edu/common/home/u1283221/miniconda3/envs/compositional/lib/python3.11/site-packages/huggingface_hub/utils/_errors.py", line 277, in hf_raise_for_status
    raise GatedRepoError(message, response) from e
huggingface_hub.utils._errors.GatedRepoError: 401 Client Error. (Request ID: Root=1-64e8f040-44a33057321d39e747431ef4;b09c47e8-ce83-46ea-af26-3a5d178d7722)

Cannot access gated repo for url https://huggingface.co/meta-llama/Llama-2-7b-chat-hf/resolve/main/tokenizer_config.json.
Repo model meta-llama/Llama-2-7b-chat-hf is gated. You must be authenticated to access it.

The above exception was the direct cause of the following exception:

Traceback (most recent call last):
  File "/uufs/chpc.utah.edu/common/home/u1283221/compositional_task_evaluation/llama2_cte.py", line 61, in <module>
    tokenizer = AutoTokenizer.from_pretrained("meta-llama/Llama-2-7b-chat-hf")
                ^^^^^^^^^^^^^^^^^^^^^^^^^^^^^^^^^^^^^^^^^^^^^^^^^^^^^^^^^^^^^^
  File "/uufs/chpc.utah.edu/common/home/u1283221/miniconda3/envs/compositional/lib/python3.11/site-packages/transformers/models/auto/tokenization_auto.py", line 677, in from_pretrained
    tokenizer_config = get_tokenizer_config(pretrained_model_name_or_path, **kwargs)
                       ^^^^^^^^^^^^^^^^^^^^^^^^^^^^^^^^^^^^^^^^^^^^^^^^^^^^^^^^^^^^^
  File "/uufs/chpc.utah.edu/common/home/u1283221/miniconda3/envs/compositional/lib/python3.11/site-packages/transformers/models/auto/tokenization_auto.py", line 510, in get_tokenizer_config
    resolved_config_file = cached_file(
                           ^^^^^^^^^^^^
  File "/uufs/chpc.utah.edu/common/home/u1283221/miniconda3/envs/compositional/lib/python3.11/site-packages/transformers/utils/hub.py", line 443, in cached_file
    raise EnvironmentError(
OSError: You are trying to access a gated repo.
Make sure to request access at https://huggingface.co/meta-llama/Llama-2-7b-chat-hf and pass a token having permission to this repo either by logging in with `huggingface-cli login` or by passing `token=<your_token>`.
